Traceback (most recent call last):
  File "/home/keyi/anaconda3/envs/artigrasp/lib/python3.8/runpy.py", line 194, in _run_module_as_main
    return _run_code(code, main_globals, None,
  File "/home/keyi/anaconda3/envs/artigrasp/lib/python3.8/runpy.py", line 87, in _run_code
    exec(code, run_globals)
  File "/home/keyi/.vscode/extensions/ms-python.debugpy-2024.10.0-linux-x64/bundled/libs/debugpy/adapter/../../debugpy/launcher/../../debugpy/__main__.py", line 39, in <module>
    cli.main()
  File "/home/keyi/.vscode/extensions/ms-python.debugpy-2024.10.0-linux-x64/bundled/libs/debugpy/adapter/../../debugpy/launcher/../../debugpy/../debugpy/server/cli.py", line 430, in main
    run()
  File "/home/keyi/.vscode/extensions/ms-python.debugpy-2024.10.0-linux-x64/bundled/libs/debugpy/adapter/../../debugpy/launcher/../../debugpy/../debugpy/server/cli.py", line 284, in run_file
    runpy.run_path(target, run_name="__main__")
  File "/home/keyi/.vscode/extensions/ms-python.debugpy-2024.10.0-linux-x64/bundled/libs/debugpy/_vendored/pydevd/_pydevd_bundle/pydevd_runpy.py", line 321, in run_path
    return _run_module_code(code, init_globals, run_name,
  File "/home/keyi/.vscode/extensions/ms-python.debugpy-2024.10.0-linux-x64/bundled/libs/debugpy/_vendored/pydevd/_pydevd_bundle/pydevd_runpy.py", line 135, in _run_module_code
    _run_code(code, mod_globals, init_globals,
  File "/home/keyi/.vscode/extensions/ms-python.debugpy-2024.10.0-linux-x64/bundled/libs/debugpy/_vendored/pydevd/_pydevd_bundle/pydevd_runpy.py", line 124, in _run_code
    exec(code, run_globals)
  File "/home/keyi/Documents/VsCodeP/research/retarget/bimanual/assistive_stable_baselines3/main/train_imitate_dexmv.py", line 104, in <module>
    env = SubprocVecEnv([create_env_fn] * args.workers, "spawn")
  File "/home/keyi/Documents/VsCodeP/research/retarget/bimanual/assistive_stable_baselines3/stable_baselines3/common/vec_env/subproc_vec_env.py", line 119, in __init__
    observation_space, action_space = self.remotes[0].recv()
  File "/home/keyi/anaconda3/envs/artigrasp/lib/python3.8/multiprocessing/connection.py", line 250, in recv
    buf = self._recv_bytes()
  File "/home/keyi/anaconda3/envs/artigrasp/lib/python3.8/multiprocessing/connection.py", line 414, in _recv_bytes
    buf = self._recv(4)
  File "/home/keyi/anaconda3/envs/artigrasp/lib/python3.8/multiprocessing/connection.py", line 379, in _recv
    chunk = read(handle, remaining)
ConnectionResetError: [Errno 104] Connection reset by peer